<mujoco model="go2_description">
  <compiler angle="radian" meshdir="assets/dae" autolimits="true"/>
  <option cone="elliptic" impratio="100" integrator="implicitfast" timestep="0.001"/>

  <default>
    <default class="go2">
      <geom friction="0.6" margin="0.001" condim="1"/>
      <joint axis="0 1 0" damping="0.02" armature="0.01" frictionloss="0.001"/>
      <motor ctrlrange="-23.7 23.7"/>
      <default class="abduction">
        <joint axis="1 0 0" range="-1.0472 1.0472"/>
      </default>
      <default class="hip">
        <default class="front_hip">
          <joint range="-1.5708 3.4907"/>
        </default>
        <default class="back_hip">
          <joint range="-0.5236 4.5379"/>
        </default>
      </default>
      <default class="knee">
        <joint range="-2.7227 -0.83776"/>
        <motor ctrlrange="-45.43 45.43"/>
      </default>
      <default class="visual">
        <geom type="mesh" contype="0" conaffinity="0" group="2"/>
      </default>
      <default class="collision">
        <geom group="3"/>
        <default class="foot">
          <geom size="0.022" pos="-0.002 0 -0.213" priority="1" solimp="0.015 1 0.031" condim="6"
            friction="0.7 0.02 0.01"/>
        </default>
      </default>
    </default>
  </default>

  <asset>
    <material name="metal" rgba=".9 .95 .95 1"/>
    <material name="black" rgba="0.1 0.1 0.1 1"/>
    <material name="white" rgba="1 1 1 1"/>
    <material name="gray" rgba="0.671705 0.692426 0.774270 1"/>

    <mesh file="base.obj"/>
    <mesh file="hip.obj"/>
    <mesh file="thigh.obj"/>
    <mesh file="thigh_mirror.obj"/>
    <mesh file="calf.obj"/>
    <mesh file="calf_mirror.obj"/>
    <mesh file="foot.obj"/>
  </asset>

  <worldbody>
    <body name="base" pos="0 0 0.445" childclass="go2">
      <inertial pos="0.021112 0 -0.005366" quat="-0.000543471 0.713435 -0.00173769 0.700719" mass="6.921" diaginertia="0.02448 0.0980771 0.107"/>
      <freejoint/>
      <geom mesh="base" material="gray" class="visual"/>
      <geom size="0.1881 0.04675 0.057" type="box" class="collision"/>
      <geom size="0.05 0.045" pos="0.285 0 0.01" type="cylinder" class="collision"/>
      <geom size="0.047" pos="0.293 0 -0.06" class="collision"/>
      <site name="imu" pos="-0.02557 0 0.04232"/>
        
      <body name="FL_hip" pos="0.1934 0.0465 0">
        <inertial pos="-0.0054 0.00194 -0.000105" quat="0.497014 0.499245 0.505462 0.498237" mass="0.678" diaginertia="0.00088403 0.000596003 0.000479967"/>
        <joint name="FL_hip_joint" pos="0 0 0" axis="1 0 0" limited="true" range="-1.0472 1.0472"/>
        <geom size="0.046 0.02" pos="0 0.08 0" quat="0.707107 0.707107 0 0" type="cylinder" class="collision"/>
        <geom mesh="hip" material="gray" class="visual"/>
        <body name="FL_thigh" pos="0 0.0955 0">
          <inertial pos="-0.00374 -0.0223 -0.0327" quat="0.829533 0.0847635 -0.0200632 0.551623" mass="1.152" diaginertia="0.00594973 0.00584149 0.000878787"/>
          <joint name="FL_thigh_joint" pos="0 0 0" axis="0 1 0" limited="true" range="-1.5708 3.4907"/>
          <geom size="0.1065 0.01225 0.017" pos="0 0 -0.1065" quat="0.707107 0 0.707107 0" type="box" class="collision"/>
          <geom mesh="thigh" material="gray" class="visual"/>
          <body name="FL_calf" pos="0 0 -0.213">
            <inertial pos="0.00629595 -0.000622121 -0.141417" quat="0.710672 0.00154099 -0.00450087 0.703508" mass="0.241352" diaginertia="0.0014901 0.00146356 5.31397e-05"/>
            <joint name="FL_calf_joint" pos="0 0 0" axis="0 1 0" limited="true" range="-2.7227 -0.83776"/>
            <geom mesh="calf" material="gray" class="visual"/>
            <geom size="0.012 0.06" pos="0.008 0 -0.06" quat="0.994493 0 -0.104807 0" type="cylinder" class="collision"/>
            <geom size="0.011 0.0325" pos="0.02 0 -0.148" quat="0.999688 0 0.0249974 0" type="cylinder" class="collision"/>
            <geom pos="0 0 -0.213" mesh="foot" class="visual" material="black"/>
            <geom name="FL_foot" class="foot"/>
          </body>
        </body>
      </body>
      <body name="FR_hip" pos="0.1934 -0.0465 0">
        <inertial pos="-0.0054 -0.00194 -0.000105" quat="0.498237 0.505462 0.499245 0.497014" mass="0.678" diaginertia="0.00088403 0.000596003 0.000479967"/>
        <joint name="FR_hip_joint" pos="0 0 0" axis="1 0 0" limited="true" range="-1.0472 1.0472"/>
        <geom size="0.046 0.02" pos="0 -0.08 0" quat="0.707107 0.707107 0 0" type="cylinder" class="collision"/>
        <geom mesh="hip" material="gray" class="visual"/>
        <body name="FR_thigh" pos="0 -0.0955 0">
          <inertial pos="-0.00374 0.0223 -0.0327" quat="0.551623 -0.0200632 0.0847635 0.829533" mass="1.152" diaginertia="0.00594973 0.00584149 0.000878787"/>
          <joint name="FR_thigh_joint" pos="0 0 0" axis="0 1 0" limited="true" range="-1.5708 3.4907"/>
          <geom size="0.1065 0.01225 0.017" pos="0 0 -0.1065" quat="0.707107 0 0.707107 0" type="box" class="collision"/>
          <geom mesh="thigh_mirror" material="gray" class="visual"/>
          <body name="FR_calf" pos="0 0 -0.213">
            <inertial pos="0.00629595 0.000622121 -0.141417" quat="0.703508 -0.00450087 0.00154099 0.710672" mass="0.241352" diaginertia="0.0014901 0.00146356 5.31397e-05"/>
            <joint name="FR_calf_joint" pos="0 0 0" axis="0 1 0" limited="true" range="-2.7227 -0.83776"/>
            <geom mesh="calf_mirror" material="gray" class="visual"/>
            <geom size="0.013 0.06" pos="0.01 0 -0.06" quat="0.995004 0 -0.0998334 0" type="cylinder" class="collision"/>
            <geom size="0.011 0.0325" pos="0.02 0 -0.148" quat="0.999688 0 0.0249974 0" type="cylinder" class="collision"/>
            <geom pos="0 0 -0.213" mesh="foot" class="visual" material="black"/>
            <geom name="FR_foot" class="foot"/>
          </body>
        </body>
      </body>
      <body name="RL_hip" pos="-0.1934 0.0465 0">
        <inertial pos="0.0054 0.00194 -0.000105" quat="0.505462 0.498237 0.497014 0.499245" mass="0.678" diaginertia="0.00088403 0.000596003 0.000479967"/>
        <joint name="RL_hip_joint" pos="0 0 0" axis="1 0 0" limited="true" range="-1.0472 1.0472"/>
        <geom size="0.046 0.02" pos="0 0.08 0" quat="0.707107 0.707107 0 0" type="cylinder" class="collision"/>
        <geom mesh="hip" material="gray" class="visual"/>
        <body name="RL_thigh" pos="0 0.0955 0">
          <inertial pos="-0.00374 -0.0223 -0.0327" quat="0.829533 0.0847635 -0.0200632 0.551623" mass="1.152" diaginertia="0.00594973 0.00584149 0.000878787"/>
          <joint name="RL_thigh_joint" pos="0 0 0" axis="0 1 0" limited="true" range="-0.5236 4.5379"/>
          <geom size="0.1065 0.01225 0.017" pos="0 0 -0.1065" quat="0.707107 0 0.707107 0" type="box" class="collision"/>
          <geom mesh="thigh" material="gray" class="visual"/>
          <body name="RL_calf" pos="0 0 -0.213">
            <inertial pos="0.00629595 -0.000622121 -0.141417" quat="0.710672 0.00154099 -0.00450087 0.703508" mass="0.241352" diaginertia="0.0014901 0.00146356 5.31397e-05"/>
            <joint name="RL_calf_joint" pos="0 0 0" axis="0 1 0" limited="true" range="-2.7227 -0.83776"/>
            <geom mesh="calf" material="gray" class="visual"/>
            <geom size="0.013 0.06" pos="0.01 0 -0.06" quat="0.995004 0 -0.0998334 0" type="cylinder" class="collision"/>
            <geom size="0.011 0.0325" pos="0.02 0 -0.148" quat="0.999688 0 0.0249974 0" type="cylinder" class="collision"/>
            <geom pos="0 0 -0.213" mesh="foot" class="visual" material="black"/>
            <geom name="RL_foot" class="foot"/>
          </body>
        </body>
      </body>
      <body name="RR_hip" pos="-0.1934 -0.0465 0">
        <inertial pos="0.0054 -0.00194 -0.000105" quat="0.499245 0.497014 0.498237 0.505462" mass="0.678" diaginertia="0.00088403 0.000596003 0.000479967"/>
        <joint name="RR_hip_joint" pos="0 0 0" axis="1 0 0" limited="true" range="-1.0472 1.0472"/>
        <geom size="0.046 0.02" pos="0 -0.08 0" quat="0.707107 0.707107 0 0" type="cylinder" class="collision"/>
        <geom mesh="hip" material="gray" class="visual"/>
        <body name="RR_thigh" pos="0 -0.0955 0">
          <inertial pos="-0.00374 0.0223 -0.0327" quat="0.551623 -0.0200632 0.0847635 0.829533" mass="1.152" diaginertia="0.00594973 0.00584149 0.000878787"/>
          <joint name="RR_thigh_joint" pos="0 0 0" axis="0 1 0" limited="true" range="-0.5236 4.5379"/>
          <geom size="0.1065 0.01225 0.017" pos="0 0 -0.1065" quat="0.707107 0 0.707107 0" type="box" class="collision"/>
          <geom mesh="thigh_mirror" material="gray" class="visual"/>
          <body name="RR_calf" pos="0 0 -0.213">
            <inertial pos="0.00629595 0.000622121 -0.141417" quat="0.703508 -0.00450087 0.00154099 0.710672" mass="0.241352" diaginertia="0.0014901 0.00146356 5.31397e-05"/>
            <joint name="RR_calf_joint" pos="0 0 0" axis="0 1 0" limited="true" range="-2.7227 -0.83776"/>
            <geom mesh="calf_mirror" material="gray" class="visual"/>
            <geom size="0.013 0.06" pos="0.01 0 -0.06" quat="0.995004 0 -0.0998334 0" type="cylinder" class="collision"/>
            <geom size="0.011 0.0325" pos="0.02 0 -0.148" quat="0.999688 0 0.0249974 0" type="cylinder" class="collision"/>
            <geom pos="0 0 -0.213" mesh="foot" class="visual" material="black"/>
            <geom name="RR_foot" class="foot"/>
          </body>
        </body>
      </body>
    </body>
  </worldbody>

  <actuator>
    <motor class="abduction" name="FL_hip" gear="1" joint="FL_hip_joint"/>
    <motor class="hip" name="FL_thigh" gear="1" joint="FL_thigh_joint"/>
    <motor class="knee" name="FL_calf" gear="1" joint="FL_calf_joint"/>
    <motor class="abduction" name="FR_hip" gear="1" joint="FR_hip_joint"/>
    <motor class="hip" name="FR_thigh" gear="1" joint="FR_thigh_joint"/>
    <motor class="knee" name="FR_calf" gear="1" joint="FR_calf_joint"/>
    <motor class="abduction" name="RL_hip" gear="1" joint="RL_hip_joint"/>
    <motor class="hip" name="RL_thigh" gear="1" joint="RL_thigh_joint"/>
    <motor class="knee" name="RL_calf" gear="1" joint="RL_calf_joint"/>
    <motor class="abduction" name="RR_hip" gear="1" joint="RR_hip_joint"/>
    <motor class="hip" name="RR_thigh" gear="1" joint="RR_thigh_joint"/>
    <motor class="knee" name="RR_calf" gear="1" joint="RR_calf_joint"/>
  </actuator>

  <keyframe>
    <key name="home" qpos="0 0 0.29 1 0 0 0 0 0.9 -1.8 0 0.9 -1.8 0 0.9 -1.8 0 0.9 -1.8"
      ctrl="0 0.9 -1.8 0 0.9 -1.8 0 0.9 -1.8 0 0.9 -1.8"/>
  </keyframe>
</mujoco>
